Traceback (most recent call last):
  File "/Users/alandmesser/anaconda3/envs/workshops/lib/python3.7/site-packages/jupyter_cache/executors/utils.py", line 56, in single_nb_execution
    record_timing=False,
  File "/Users/alandmesser/anaconda3/envs/workshops/lib/python3.7/site-packages/nbclient/client.py", line 1112, in execute
    return NotebookClient(nb=nb, resources=resources, km=km, **kwargs).execute()
  File "/Users/alandmesser/anaconda3/envs/workshops/lib/python3.7/site-packages/nbclient/util.py", line 74, in wrapped
    return just_run(coro(*args, **kwargs))
  File "/Users/alandmesser/anaconda3/envs/workshops/lib/python3.7/site-packages/nbclient/util.py", line 53, in just_run
    return loop.run_until_complete(coro)
  File "/Users/alandmesser/anaconda3/envs/workshops/lib/python3.7/asyncio/base_events.py", line 583, in run_until_complete
    return future.result()
  File "/Users/alandmesser/anaconda3/envs/workshops/lib/python3.7/site-packages/nbclient/client.py", line 554, in async_execute
    cell, index, execution_count=self.code_cells_executed + 1
  File "/Users/alandmesser/anaconda3/envs/workshops/lib/python3.7/site-packages/nbclient/client.py", line 857, in async_execute_cell
    self._check_raise_for_error(cell, exec_reply)
  File "/Users/alandmesser/anaconda3/envs/workshops/lib/python3.7/site-packages/nbclient/client.py", line 760, in _check_raise_for_error
    raise CellExecutionError.from_cell_and_msg(cell, exec_reply_content)
nbclient.exceptions.CellExecutionError: An error occurred while executing the following cell:
------------------
X = pd.DataFrame({'a':[1000,2000,9999,1500],'b':[1,0,1,2],'c':[2,-16,1,0]}, index=[1,2,3,4])
X
------------------

[0;31m---------------------------------------------------------------------------[0m
[0;31mNameError[0m                                 Traceback (most recent call last)
[0;32m<ipython-input-2-97902140a97e>[0m in [0;36m<module>[0;34m[0m
[0;32m----> 1[0;31m [0mX[0m [0;34m=[0m [0mpd[0m[0;34m.[0m[0mDataFrame[0m[0;34m([0m[0;34m{[0m[0;34m'a'[0m[0;34m:[0m[0;34m[[0m[0;36m1000[0m[0;34m,[0m[0;36m2000[0m[0;34m,[0m[0;36m9999[0m[0;34m,[0m[0;36m1500[0m[0;34m][0m[0;34m,[0m[0;34m'b'[0m[0;34m:[0m[0;34m[[0m[0;36m1[0m[0;34m,[0m[0;36m0[0m[0;34m,[0m[0;36m1[0m[0;34m,[0m[0;36m2[0m[0;34m][0m[0;34m,[0m[0;34m'c'[0m[0;34m:[0m[0;34m[[0m[0;36m2[0m[0;34m,[0m[0;34m-[0m[0;36m16[0m[0;34m,[0m[0;36m1[0m[0;34m,[0m[0;36m0[0m[0;34m][0m[0;34m}[0m[0;34m,[0m [0mindex[0m[0;34m=[0m[0;34m[[0m[0;36m1[0m[0;34m,[0m[0;36m2[0m[0;34m,[0m[0;36m3[0m[0;34m,[0m[0;36m4[0m[0;34m][0m[0;34m)[0m[0;34m[0m[0;34m[0m[0m
[0m[1;32m      2[0m [0mX[0m[0;34m[0m[0;34m[0m[0m

[0;31mNameError[0m: name 'pd' is not defined
NameError: name 'pd' is not defined

